Workbook

Sheet Amazon Books Inventory Team

Sheet Sources >>

Sheet Stock
A1: =IFERROR(__xludf.DUMMYFUNCTION("IMPORTRANGE(""https://docs.google.com/spreadsheets/d/1yOpZnyZ5ouw2C51zn4VNSNmNNrizgIE5YAyno7ltBiE/edit"",""stock!A:Z"")"),"product_id") -> product_id | B1: =IFERROR(__xludf.DUMMYFUNCTION("""COMPUTED_VALUE"""),"new") -> new | C1: =IFERROR(__xludf.DUMMYFUNCTION("""COMPUTED_VALUE"""),"forecast_stock") -> forecast_stock | D1: =IFERROR(__xludf.DUMMYFUNCTION("""COMPUTED_VALUE"""),"stock") -> stock
A2: =IFERROR(__xludf.DUMMYFUNCTION("""COMPUTED_VALUE"""),112463.0) -> 112463 | B2: =IFERROR(__xludf.DUMMYFUNCTION("""COMPUTED_VALUE"""),0.0) -> 0 | C2: =IFERROR(__xludf.DUMMYFUNCTION("""COMPUTED_VALUE"""),320.0) -> 320 | D2: =IFERROR(__xludf.DUMMYFUNCTION("""COMPUTED_VALUE"""),320.0) -> 320
A3: =IFERROR(__xludf.DUMMYFUNCTION("""COMPUTED_VALUE"""),112481.0) -> 112481 | B3: =IFERROR(__xludf.DUMMYFUNCTION("""COMPUTED_VALUE"""),0.0) -> 0 | C3: =IFERROR(__xludf.DUMMYFUNCTION("""COMPUTED_VALUE"""),0.0) -> 0 | D3: =IFERROR(__xludf.DUMMYFUNCTION("""COMPUTED_VALUE"""),0.0) -> 0
A4: =IFERROR(__xludf.DUMMYFUNCTION("""COMPUTED_VALUE"""),13346.0) -> 13346 | B4: =IFERROR(__xludf.DUMMYFUNCTION("""COMPUTED_VALUE"""),1.0) -> 1 | C4: =IFERROR(__xludf.DUMMYFUNCTION("""COMPUTED_VALUE"""),100.0) -> 100 | D4: =IFERROR(__xludf.DUMMYFUNCTION("""COMPUTED_VALUE"""),100.0) -> 100
A5: =IFERROR(__xludf.DUMMYFUNCTION("""COMPUTED_VALUE"""),112454.0) -> 112454 | B5: =IFERROR(__xludf.DUMMYFUNCTION("""COMPUTED_VALUE"""),0.0) -> 0 | C5: =IFERROR(__xludf.DUMMYFUNCTION("""COMPUTED_VALUE"""),277.0) -> 277 | D5: =IFERROR(__xludf.DUMMYFUNCTION("""COMPUTED_VALUE"""),268.0) -> 268
A6: =IFERROR(__xludf.DUMMYFUNCTION("""COMPUTED_VALUE"""),112461.0) -> 112461 | B6: =IFERROR(__xludf.DUMMYFUNCTION("""COMPUTED_VALUE"""),0.0) -> 0 | C6: =IFERROR(__xludf.DUMMYFUNCTION("""COMPUTED_VALUE"""),971.0) -> 971 | D6: =IFERROR(__xludf.DUMMYFUNCTION("""COMPUTED_VALUE"""),472.0) -> 472
A7: =IFERROR(__xludf.DUMMYFUNCTION("""COMPUTED_VALUE"""),106532.0) -> 106532 | B7: =IFERROR(__xludf.DUMMYFUNCTION("""COMPUTED_VALUE"""),0.0) -> 0 | C7: =IFERROR(__xludf.DUMMYFUNCTION("""COMPUTED_VALUE"""),63.0) -> 63 | D7: =IFERROR(__xludf.DUMMYFUNCTION("""COMPUTED_VALUE"""),63.0) -> 63
A8: =IFERROR(__xludf.DUMMYFUNCTION("""COMPUTED_VALUE"""),121135.0) -> 121135 | B8: =IFERROR(__xludf.DUMMYFUNCTION("""COMPUTED_VALUE"""),1.0) -> 1 | C8: =IFERROR(__xludf.DUMMYFUNCTION("""COMPUTED_VALUE"""),40.0) -> 40 | D8: =IFERROR(__xludf.DUMMYFUNCTION("""COMPUTED_VALUE"""),33.0) -> 33
A9: =IFERROR(__xludf.DUMMYFUNCTION("""COMPUTED_VALUE"""),128362.0) -> 128362 | B9: =IFERROR(__xludf.DUMMYFUNCTION("""COMPUTED_VALUE"""),1.0) -> 1 | C9: =IFERROR(__xludf.DUMMYFUNCTION("""COMPUTED_VALUE"""),269.0) -> 269 | D9: =IFERROR(__xludf.DUMMYFUNCTION("""COMPUTED_VALUE"""),104.0) -> 104
A10: =IFERROR(__xludf.DUMMYFUNCTION("""COMPUTED_VALUE"""),71200.0) -> 71200 | B10: =IFERROR(__xludf.DUMMYFUNCTION("""COMPUTED_VALUE"""),0.0) -> 0 | C10: =IFERROR(__xludf.DUMMYFUNCTION("""COMPUTED_VALUE"""),164.0) -> 164 | D10: =IFERROR(__xludf.DUMMYFUNCTION("""COMPUTED_VALUE"""),152.0) -> 152
A11: =IFERROR(__xludf.DUMMYFUNCTION("""COMPUTED_VALUE"""),19812.0) -> 19812 | B11: =IFERROR(__xludf.DUMMYFUNCTION("""COMPUTED_VALUE"""),0.0) -> 0 | C11: =IFERROR(__xludf.DUMMYFUNCTION("""COMPUTED_VALUE"""),489.0) -> 489 | D11: =IFERROR(__xludf.DUMMYFUNCTION("""COMPUTED_VALUE"""),393.0) -> 393
A12: =IFERROR(__xludf.DUMMYFUNCTION("""COMPUTED_VALUE"""),122259.0) -> 122259 | B12: =IFERROR(__xludf.DUMMYFUNCTION("""COMPUTED_VALUE"""),1.0) -> 1 | C12: =IFERROR(__xludf.DUMMYFUNCTION("""COMPUTED_VALUE"""),104.0) -> 104 | D12: =IFERROR(__xludf.DUMMYFUNCTION("""COMPUTED_VALUE"""),104.0) -> 104
A13: =IFERROR(__xludf.DUMMYFUNCTION("""COMPUTED_VALUE"""),199526.0) -> 199526 | B13: =IFERROR(__xludf.DUMMYFUNCTION("""COMPUTED_VALUE"""),0.0) -> 0 | C13: =IFERROR(__xludf.DUMMYFUNCTION("""COMPUTED_VALUE"""),63.0) -> 63 | D13: =IFERROR(__xludf.DUMMYFUNCTION("""COMPUTED_VALUE"""),60.0) -> 60
A14: =IFERROR(__xludf.DUMMYFUNCTION("""COMPUTED_VALUE"""),140581.0) -> 140581 | B14: =IFERROR(__xludf.DUMMYFUNCTION("""COMPUTED_VALUE"""),0.0) -> 0 | C14: =IFERROR(__xludf.DUMMYFUNCTION("""COMPUTED_VALUE"""),14.0) -> 14 | D14: =IFERROR(__xludf.DUMMYFUNCTION("""COMPUTED_VALUE"""),9.0) -> 9
A15: =IFERROR(__xludf.DUMMYFUNCTION("""COMPUTED_VALUE"""),118383.0) -> 118383 | B15: =IFERROR(__xludf.DUMMYFUNCTION("""COMPUTED_VALUE"""),0.0) -> 0 | C15: =IFERROR(__xludf.DUMMYFUNCTION("""COMPUTED_VALUE"""),256.0) -> 256 | D15: =IFERROR(__xludf.DUMMYFUNCTION("""COMPUTED_VALUE"""),256.0) -> 256
A16: =IFERROR(__xludf.DUMMYFUNCTION("""COMPUTED_VALUE"""),122262.0) -> 122262 | B16: =IFERROR(__xludf.DUMMYFUNCTION("""COMPUTED_VALUE"""),0.0) -> 0 | C16: =IFERROR(__xludf.DUMMYFUNCTION("""COMPUTED_VALUE"""),326.0) -> 326 | D16: =IFERROR(__xludf.DUMMYFUNCTION("""COMPUTED_VALUE"""),326.0) -> 326
A17: =IFERROR(__xludf.DUMMYFUNCTION("""COMPUTED_VALUE"""),141879.0) -> 141879 | B17: =IFERROR(__xludf.DUMMYFUNCTION("""COMPUTED_VALUE"""),0.0) -> 0 | C17: =IFERROR(__xludf.DUMMYFUNCTION("""COMPUTED_VALUE"""),11.0) -> 11 | D17: =IFERROR(__xludf.DUMMYFUNCTION("""COMPUTED_VALUE"""),11.0) -> 11
A18: =IFERROR(__xludf.DUMMYFUNCTION("""COMPUTED_VALUE"""),19826.0) -> 19826 | B18: =IFERROR(__xludf.DUMMYFUNCTION("""COMPUTED_VALUE"""),0.0) -> 0 | C18: =IFERROR(__xludf.DUMMYFUNCTION("""COMPUTED_VALUE"""),210.0) -> 210 | D18: =IFERROR(__xludf.DUMMYFUNCTION("""COMPUTED_VALUE"""),103.0) -> 103
A19: =IFERROR(__xludf.DUMMYFUNCTION("""COMPUTED_VALUE"""),93039.0) -> 93039 | B19: =IFERROR(__xludf.DUMMYFUNCTION("""COMPUTED_VALUE"""),0.0) -> 0 | C19: =IFERROR(__xludf.DUMMYFUNCTION("""COMPUTED_VALUE"""),68.0) -> 68 | D19: =IFERROR(__xludf.DUMMYFUNCTION("""COMPUTED_VALUE"""),68.0) -> 68
A20: =IFERROR(__xludf.DUMMYFUNCTION("""COMPUTED_VALUE"""),128213.0) -> 128213 | B20: =IFERROR(__xludf.DUMMYFUNCTION("""COMPUTED_VALUE"""),0.0) -> 0 | C20: =IFERROR(__xludf.DUMMYFUNCTION("""COMPUTED_VALUE"""),318.0) -> 318 | D20: =IFERROR(__xludf.DUMMYFUNCTION("""COMPUTED_VALUE"""),162.0) -> 162
A21: =IFERROR(__xludf.DUMMYFUNCTION("""COMPUTED_VALUE"""),83797.0) -> 83797 | B21: =IFERROR(__xludf.DUMMYFUNCTION("""COMPUTED_VALUE"""),0.0) -> 0 | C21: =IFERROR(__xludf.DUMMYFUNCTION("""COMPUTED_VALUE"""),43.0) -> 43 | D21: =IFERROR(__xludf.DUMMYFUNCTION("""COMPUTED_VALUE"""),43.0) -> 43
A22: =IFERROR(__xludf.DUMMYFUNCTION("""COMPUTED_VALUE"""),19831.0) -> 19831 | B22: =IFERROR(__xludf.DUMMYFUNCTION("""COMPUTED_VALUE"""),0.0) -> 0 | C22: =IFERROR(__xludf.DUMMYFUNCTION("""COMPUTED_VALUE"""),185.0) -> 185 | D22: =IFERROR(__xludf.DUMMYFUNCTION("""COMPUTED_VALUE"""),134.0) -> 134
A23: =IFERROR(__xludf.DUMMYFUNCTION("""COMPUTED_VALUE"""),93025.0) -> 93025 | B23: =IFERROR(__xludf.DUMMYFUNCTION("""COMPUTED_VALUE"""),0.0) -> 0 | C23: =IFERROR(__xludf.DUMMYFUNCTION("""COMPUTED_VALUE"""),305.0) -> 305 | D23: =IFERROR(__xludf.DUMMYFUNCTION("""COMPUTED_VALUE"""),305.0) -> 305
A24: =IFERROR(__xludf.DUMMYFUNCTION("""COMPUTED_VALUE"""),81624.0) -> 81624 | B24: =IFERROR(__xludf.DUMMYFUNCTION("""COMPUTED_VALUE"""),1.0) -> 1 | C24: =IFERROR(__xludf.DUMMYFUNCTION("""COMPUTED_VALUE"""),84.0) -> 84 | D24: =IFERROR(__xludf.DUMMYFUNCTION("""COMPUTED_VALUE"""),84.0) -> 84
A25: =IFERROR(__xludf.DUMMYFUNCTION("""COMPUTED_VALUE"""),92913.0) -> 92913 | B25: =IFERROR(__xludf.DUMMYFUNCTION("""COMPUTED_VALUE"""),0.0) -> 0 | C25: =IFERROR(__xludf.DUMMYFUNCTION("""COMPUTED_VALUE"""),96.0) -> 96 | D25: =IFERROR(__xludf.DUMMYFUNCTION("""COMPUTED_VALUE"""),96.0) -> 96
A26: =IFERROR(__xludf.DUMMYFUNCTION("""COMPUTED_VALUE"""),126983.0) -> 126983 | B26: =IFERROR(__xludf.DUMMYFUNCTION("""COMPUTED_VALUE"""),0.0) -> 0 | C26: =IFERROR(__xludf.DUMMYFUNCTION("""COMPUTED_VALUE"""),176.0) -> 176 | D26: =IFERROR(__xludf.DUMMYFUNCTION("""COMPUTED_VALUE"""),71.0) -> 71
A27: =IFERROR(__xludf.DUMMYFUNCTION("""COMPUTED_VALUE"""),118226.0) -> 118226 | B27: =IFERROR(__xludf.DUMMYFUNCTION("""COMPUTED_VALUE"""),0.0) -> 0 | C27: =IFERROR(__xludf.DUMMYFUNCTION("""COMPUTED_VALUE"""),130.0) -> 130 | D27: =IFERROR(__xludf.DUMMYFUNCTION("""COMPUTED_VALUE"""),130.0) -> 130
A28: =IFERROR(__xludf.DUMMYFUNCTION("""COMPUTED_VALUE"""),48618.0) -> 48618 | B28: =IFERROR(__xludf.DUMMYFUNCTION("""COMPUTED_VALUE"""),1.0) -> 1 | C28: =IFERROR(__xludf.DUMMYFUNCTION("""COMPUTED_VALUE"""),84.0) -> 84 | D28: =IFERROR(__xludf.DUMMYFUNCTION("""COMPUTED_VALUE"""),84.0) -> 84
A29: =IFERROR(__xludf.DUMMYFUNCTION("""COMPUTED_VALUE"""),93037.0) -> 93037 | B29: =IFERROR(__xludf.DUMMYFUNCTION("""COMPUTED_VALUE"""),0.0) -> 0 | C29: =IFERROR(__xludf.DUMMYFUNCTION("""COMPUTED_VALUE"""),604.0) -> 604 | D29: =IFERROR(__xludf.DUMMYFUNCTION("""COMPUTED_VALUE"""),604.0) -> 604
A30: =IFERROR(__xludf.DUMMYFUNCTION("""COMPUTED_VALUE"""),126984.0) -> 126984 | B30: =IFERROR(__xludf.DUMMYFUNCTION("""COMPUTED_VALUE"""),0.0) -> 0 | C30: =IFERROR(__xludf.DUMMYFUNCTION("""COMPUTED_VALUE"""),26.0) -> 26 | D30: =IFERROR(__xludf.DUMMYFUNCTION("""COMPUTED_VALUE"""),6.0) -> 6
A31: =IFERROR(__xludf.DUMMYFUNCTION("""COMPUTED_VALUE"""),47393.0) -> 47393 | B31: =IFERROR(__xludf.DUMMYFUNCTION("""COMPUTED_VALUE"""),0.0) -> 0 | C31: =IFERROR(__xludf.DUMMYFUNCTION("""COMPUTED_VALUE"""),982.0) -> 982 | D31: =IFERROR(__xludf.DUMMYFUNCTION("""COMPUTED_VALUE"""),609.0) -> 609
A32: =IFERROR(__xludf.DUMMYFUNCTION("""COMPUTED_VALUE"""),128214.0) -> 128214 | B32: =IFERROR(__xludf.DUMMYFUNCTION("""COMPUTED_VALUE"""),0.0) -> 0 | C32: =IFERROR(__xludf.DUMMYFUNCTION("""COMPUTED_VALUE"""),79.0) -> 79 | D32: =IFERROR(__xludf.DUMMYFUNCTION("""COMPUTED_VALUE"""),79.0) -> 79
A33: =IFERROR(__xludf.DUMMYFUNCTION("""COMPUTED_VALUE"""),83802.0) -> 83802 | B33: =IFERROR(__xludf.DUMMYFUNCTION("""COMPUTED_VALUE"""),0.0) -> 0 | C33: =IFERROR(__xludf.DUMMYFUNCTION("""COMPUTED_VALUE"""),31.0) -> 31 | D33: =IFERROR(__xludf.DUMMYFUNCTION("""COMPUTED_VALUE"""),23.0) -> 23
A34: =IFERROR(__xludf.DUMMYFUNCTION("""COMPUTED_VALUE"""),48625.0) -> 48625 | B34: =IFERROR(__xludf.DUMMYFUNCTION("""COMPUTED_VALUE"""),1.0) -> 1 | C34: =IFERROR(__xludf.DUMMYFUNCTION("""COMPUTED_VALUE"""),96.0) -> 96 | D34: =IFERROR(__xludf.DUMMYFUNCTION("""COMPUTED_VALUE"""),96.0) -> 96
A35: =IFERROR(__xludf.DUMMYFUNCTION("""COMPUTED_VALUE"""),83602.0) -> 83602 | B35: =IFERROR(__xludf.DUMMYFUNCTION("""COMPUTED_VALUE"""),0.0) -> 0 | C35: =IFERROR(__xludf.DUMMYFUNCTION("""COMPUTED_VALUE"""),79.0) -> 79 | D35: =IFERROR(__xludf.DUMMYFUNCTION("""COMPUTED_VALUE"""),79.0) -> 79
A36: =IFERROR(__xludf.DUMMYFUNCTION("""COMPUTED_VALUE"""),98867.0) -> 98867 | B36: =IFERROR(__xludf.DUMMYFUNCTION("""COMPUTED_VALUE"""),0.0) -> 0 | C36: =IFERROR(__xludf.DUMMYFUNCTION("""COMPUTED_VALUE"""),186.0) -> 186 | D36: =IFERROR(__xludf.DUMMYFUNCTION("""COMPUTED_VALUE"""),186.0) -> 186
A37: =IFERROR(__xludf.DUMMYFUNCTION("""COMPUTED_VALUE"""),127042.0) -> 127042 | B37: =IFERROR(__xludf.DUMMYFUNCTION("""COMPUTED_VALUE"""),0.0) -> 0 | C37: =IFERROR(__xludf.DUMMYFUNCTION("""COMPUTED_VALUE"""),418.0) -> 418 | D37: =IFERROR(__xludf.DUMMYFUNCTION("""COMPUTED_VALUE"""),418.0) -> 418
A38: =IFERROR(__xludf.DUMMYFUNCTION("""COMPUTED_VALUE"""),127241.0) -> 127241 | B38: =IFERROR(__xludf.DUMMYFUNCTION("""COMPUTED_VALUE"""),0.0) -> 0 | C38: =IFERROR(__xludf.DUMMYFUNCTION("""COMPUTED_VALUE"""),98.0) -> 98 | D38: =IFERROR(__xludf.DUMMYFUNCTION("""COMPUTED_VALUE"""),98.0) -> 98
A39: =IFERROR(__xludf.DUMMYFUNCTION("""COMPUTED_VALUE"""),118220.0) -> 118220 | B39: =IFERROR(__xludf.DUMMYFUNCTION("""COMPUTED_VALUE"""),0.0) -> 0 | C39: =IFERROR(__xludf.DUMMYFUNCTION("""COMPUTED_VALUE"""),34.0) -> 34 | D39: =IFERROR(__xludf.DUMMYFUNCTION("""COMPUTED_VALUE"""),34.0) -> 34
A40: =IFERROR(__xludf.DUMMYFUNCTION("""COMPUTED_VALUE"""),128216.0) -> 128216 | B40: =IFERROR(__xludf.DUMMYFUNCTION("""COMPUTED_VALUE"""),0.0) -> 0 | C40: =IFERROR(__xludf.DUMMYFUNCTION("""COMPUTED_VALUE"""),141.0) -> 141 | D40: =IFERROR(__xludf.DUMMYFUNCTION("""COMPUTED_VALUE"""),141.0) -> 141
...

Sheet Sales from Stock
A1: =IFERROR(__xludf.DUMMYFUNCTION("IMPORTRANGE(""https://docs.google.com/spreadsheets/d/1yOpZnyZ5ouw2C51zn4VNSNmNNrizgIE5YAyno7ltBiE/edit"",""stock!A:Z"")"),"product_id") -> product_id | B1: =IFERROR(__xludf.DUMMYFUNCTION("""COMPUTED_VALUE"""),"new") -> new | C1: =IFERROR(__xludf.DUMMYFUNCTION("""COMPUTED_VALUE"""),"forecast_stock") -> forecast_stock | D1: =IFERROR(__xludf.DUMMYFUNCTION("""COMPUTED_VALUE"""),"stock") -> stock
A2: =IFERROR(__xludf.DUMMYFUNCTION("""COMPUTED_VALUE"""),112463.0) -> 112463 | B2: =IFERROR(__xludf.DUMMYFUNCTION("""COMPUTED_VALUE"""),0.0) -> 0 | C2: =IFERROR(__xludf.DUMMYFUNCTION("""COMPUTED_VALUE"""),320.0) -> 320 | D2: =IFERROR(__xludf.DUMMYFUNCTION("""COMPUTED_VALUE"""),320.0) -> 320
A3: =IFERROR(__xludf.DUMMYFUNCTION("""COMPUTED_VALUE"""),112481.0) -> 112481 | B3: =IFERROR(__xludf.DUMMYFUNCTION("""COMPUTED_VALUE"""),0.0) -> 0 | C3: =IFERROR(__xludf.DUMMYFUNCTION("""COMPUTED_VALUE"""),0.0) -> 0 | D3: =IFERROR(__xludf.DUMMYFUNCTION("""COMPUTED_VALUE"""),0.0) -> 0
A4: =IFERROR(__xludf.DUMMYFUNCTION("""COMPUTED_VALUE"""),13346.0) -> 13346 | B4: =IFERROR(__xludf.DUMMYFUNCTION("""COMPUTED_VALUE"""),1.0) -> 1 | C4: =IFERROR(__xludf.DUMMYFUNCTION("""COMPUTED_VALUE"""),100.0) -> 100 | D4: =IFERROR(__xludf.DUMMYFUNCTION("""COMPUTED_VALUE"""),100.0) -> 100
A5: =IFERROR(__xludf.DUMMYFUNCTION("""COMPUTED_VALUE"""),112454.0) -> 112454 | B5: =IFERROR(__xludf.DUMMYFUNCTION("""COMPUTED_VALUE"""),0.0) -> 0 | C5: =IFERROR(__xludf.DUMMYFUNCTION("""COMPUTED_VALUE"""),277.0) -> 277 | D5: =IFERROR(__xludf.DUMMYFUNCTION("""COMPUTED_VALUE"""),268.0) -> 268
A6: =IFERROR(__xludf.DUMMYFUNCTION("""COMPUTED_VALUE"""),112461.0) -> 112461 | B6: =IFERROR(__xludf.DUMMYFUNCTION("""COMPUTED_VALUE"""),0.0) -> 0 | C6: =IFERROR(__xludf.DUMMYFUNCTION("""COMPUTED_VALUE"""),971.0) -> 971 | D6: =IFERROR(__xludf.DUMMYFUNCTION("""COMPUTED_VALUE"""),472.0) -> 472
A7: =IFERROR(__xludf.DUMMYFUNCTION("""COMPUTED_VALUE"""),106532.0) -> 106532 | B7: =IFERROR(__xludf.DUMMYFUNCTION("""COMPUTED_VALUE"""),0.0) -> 0 | C7: =IFERROR(__xludf.DUMMYFUNCTION("""COMPUTED_VALUE"""),63.0) -> 63 | D7: =IFERROR(__xludf.DUMMYFUNCTION("""COMPUTED_VALUE"""),63.0) -> 63
A8: =IFERROR(__xludf.DUMMYFUNCTION("""COMPUTED_VALUE"""),121135.0) -> 121135 | B8: =IFERROR(__xludf.DUMMYFUNCTION("""COMPUTED_VALUE"""),1.0) -> 1 | C8: =IFERROR(__xludf.DUMMYFUNCTION("""COMPUTED_VALUE"""),40.0) -> 40 | D8: =IFERROR(__xludf.DUMMYFUNCTION("""COMPUTED_VALUE"""),33.0) -> 33
A9: =IFERROR(__xludf.DUMMYFUNCTION("""COMPUTED_VALUE"""),128362.0) -> 128362 | B9: =IFERROR(__xludf.DUMMYFUNCTION("""COMPUTED_VALUE"""),1.0) -> 1 | C9: =IFERROR(__xludf.DUMMYFUNCTION("""COMPUTED_VALUE"""),269.0) -> 269 | D9: =IFERROR(__xludf.DUMMYFUNCTION("""COMPUTED_VALUE"""),104.0) -> 104
A10: =IFERROR(__xludf.DUMMYFUNCTION("""COMPUTED_VALUE"""),71200.0) -> 71200 | B10: =IFERROR(__xludf.DUMMYFUNCTION("""COMPUTED_VALUE"""),0.0) -> 0 | C10: =IFERROR(__xludf.DUMMYFUNCTION("""COMPUTED_VALUE"""),164.0) -> 164 | D10: =IFERROR(__xludf.DUMMYFUNCTION("""COMPUTED_VALUE"""),152.0) -> 152
A11: =IFERROR(__xludf.DUMMYFUNCTION("""COMPUTED_VALUE"""),19812.0) -> 19812 | B11: =IFERROR(__xludf.DUMMYFUNCTION("""COMPUTED_VALUE"""),0.0) -> 0 | C11: =IFERROR(__xludf.DUMMYFUNCTION("""COMPUTED_VALUE"""),489.0) -> 489 | D11: =IFERROR(__xludf.DUMMYFUNCTION("""COMPUTED_VALUE"""),393.0) -> 393
A12: =IFERROR(__xludf.DUMMYFUNCTION("""COMPUTED_VALUE"""),122259.0) -> 122259 | B12: =IFERROR(__xludf.DUMMYFUNCTION("""COMPUTED_VALUE"""),1.0) -> 1 | C12: =IFERROR(__xludf.DUMMYFUNCTION("""COMPUTED_VALUE"""),104.0) -> 104 | D12: =IFERROR(__xludf.DUMMYFUNCTION("""COMPUTED_VALUE"""),104.0) -> 104
A13: =IFERROR(__xludf.DUMMYFUNCTION("""COMPUTED_VALUE"""),199526.0) -> 199526 | B13: =IFERROR(__xludf.DUMMYFUNCTION("""COMPUTED_VALUE"""),0.0) -> 0 | C13: =IFERROR(__xludf.DUMMYFUNCTION("""COMPUTED_VALUE"""),63.0) -> 63 | D13: =IFERROR(__xludf.DUMMYFUNCTION("""COMPUTED_VALUE"""),60.0) -> 60
A14: =IFERROR(__xludf.DUMMYFUNCTION("""COMPUTED_VALUE"""),140581.0) -> 140581 | B14: =IFERROR(__xludf.DUMMYFUNCTION("""COMPUTED_VALUE"""),0.0) -> 0 | C14: =IFERROR(__xludf.DUMMYFUNCTION("""COMPUTED_VALUE"""),14.0) -> 14 | D14: =IFERROR(__xludf.DUMMYFUNCTION("""COMPUTED_VALUE"""),9.0) -> 9
A15: =IFERROR(__xludf.DUMMYFUNCTION("""COMPUTED_VALUE"""),118383.0) -> 118383 | B15: =IFERROR(__xludf.DUMMYFUNCTION("""COMPUTED_VALUE"""),0.0) -> 0 | C15: =IFERROR(__xludf.DUMMYFUNCTION("""COMPUTED_VALUE"""),256.0) -> 256 | D15: =IFERROR(__xludf.DUMMYFUNCTION("""COMPUTED_VALUE"""),256.0) -> 256
A16: =IFERROR(__xludf.DUMMYFUNCTION("""COMPUTED_VALUE"""),122262.0) -> 122262 | B16: =IFERROR(__xludf.DUMMYFUNCTION("""COMPUTED_VALUE"""),0.0) -> 0 | C16: =IFERROR(__xludf.DUMMYFUNCTION("""COMPUTED_VALUE"""),326.0) -> 326 | D16: =IFERROR(__xludf.DUMMYFUNCTION("""COMPUTED_VALUE"""),326.0) -> 326
A17: =IFERROR(__xludf.DUMMYFUNCTION("""COMPUTED_VALUE"""),141879.0) -> 141879 | B17: =IFERROR(__xludf.DUMMYFUNCTION("""COMPUTED_VALUE"""),0.0) -> 0 | C17: =IFERROR(__xludf.DUMMYFUNCTION("""COMPUTED_VALUE"""),11.0) -> 11 | D17: =IFERROR(__xludf.DUMMYFUNCTION("""COMPUTED_VALUE"""),11.0) -> 11
A18: =IFERROR(__xludf.DUMMYFUNCTION("""COMPUTED_VALUE"""),19826.0) -> 19826 | B18: =IFERROR(__xludf.DUMMYFUNCTION("""COMPUTED_VALUE"""),0.0) -> 0 | C18: =IFERROR(__xludf.DUMMYFUNCTION("""COMPUTED_VALUE"""),210.0) -> 210 | D18: =IFERROR(__xludf.DUMMYFUNCTION("""COMPUTED_VALUE"""),103.0) -> 103
A19: =IFERROR(__xludf.DUMMYFUNCTION("""COMPUTED_VALUE"""),93039.0) -> 93039 | B19: =IFERROR(__xludf.DUMMYFUNCTION("""COMPUTED_VALUE"""),0.0) -> 0 | C19: =IFERROR(__xludf.DUMMYFUNCTION("""COMPUTED_VALUE"""),68.0) -> 68 | D19: =IFERROR(__xludf.DUMMYFUNCTION("""COMPUTED_VALUE"""),68.0) -> 68
A20: =IFERROR(__xludf.DUMMYFUNCTION("""COMPUTED_VALUE"""),128213.0) -> 128213 | B20: =IFERROR(__xludf.DUMMYFUNCTION("""COMPUTED_VALUE"""),0.0) -> 0 | C20: =IFERROR(__xludf.DUMMYFUNCTION("""COMPUTED_VALUE"""),318.0) -> 318 | D20: =IFERROR(__xludf.DUMMYFUNCTION("""COMPUTED_VALUE"""),162.0) -> 162
A21: =IFERROR(__xludf.DUMMYFUNCTION("""COMPUTED_VALUE"""),83797.0) -> 83797 | B21: =IFERROR(__xludf.DUMMYFUNCTION("""COMPUTED_VALUE"""),0.0) -> 0 | C21: =IFERROR(__xludf.DUMMYFUNCTION("""COMPUTED_VALUE"""),43.0) -> 43 | D21: =IFERROR(__xludf.DUMMYFUNCTION("""COMPUTED_VALUE"""),43.0) -> 43
A22: =IFERROR(__xludf.DUMMYFUNCTION("""COMPUTED_VALUE"""),19831.0) -> 19831 | B22: =IFERROR(__xludf.DUMMYFUNCTION("""COMPUTED_VALUE"""),0.0) -> 0 | C22: =IFERROR(__xludf.DUMMYFUNCTION("""COMPUTED_VALUE"""),185.0) -> 185 | D22: =IFERROR(__xludf.DUMMYFUNCTION("""COMPUTED_VALUE"""),134.0) -> 134
A23: =IFERROR(__xludf.DUMMYFUNCTION("""COMPUTED_VALUE"""),93025.0) -> 93025 | B23: =IFERROR(__xludf.DUMMYFUNCTION("""COMPUTED_VALUE"""),0.0) -> 0 | C23: =IFERROR(__xludf.DUMMYFUNCTION("""COMPUTED_VALUE"""),305.0) -> 305 | D23: =IFERROR(__xludf.DUMMYFUNCTION("""COMPUTED_VALUE"""),305.0) -> 305
A24: =IFERROR(__xludf.DUMMYFUNCTION("""COMPUTED_VALUE"""),81624.0) -> 81624 | B24: =IFERROR(__xludf.DUMMYFUNCTION("""COMPUTED_VALUE"""),1.0) -> 1 | C24: =IFERROR(__xludf.DUMMYFUNCTION("""COMPUTED_VALUE"""),84.0) -> 84 | D24: =IFERROR(__xludf.DUMMYFUNCTION("""COMPUTED_VALUE"""),84.0) -> 84
A25: =IFERROR(__xludf.DUMMYFUNCTION("""COMPUTED_VALUE"""),92913.0) -> 92913 | B25: =IFERROR(__xludf.DUMMYFUNCTION("""COMPUTED_VALUE"""),0.0) -> 0 | C25: =IFERROR(__xludf.DUMMYFUNCTION("""COMPUTED_VALUE"""),96.0) -> 96 | D25: =IFERROR(__xludf.DUMMYFUNCTION("""COMPUTED_VALUE"""),96.0) -> 96
A26: =IFERROR(__xludf.DUMMYFUNCTION("""COMPUTED_VALUE"""),126983.0) -> 126983 | B26: =IFERROR(__xludf.DUMMYFUNCTION("""COMPUTED_VALUE"""),0.0) -> 0 | C26: =IFERROR(__xludf.DUMMYFUNCTION("""COMPUTED_VALUE"""),176.0) -> 176 | D26: =IFERROR(__xludf.DUMMYFUNCTION("""COMPUTED_VALUE"""),71.0) -> 71
A27: =IFERROR(__xludf.DUMMYFUNCTION("""COMPUTED_VALUE"""),118226.0) -> 118226 | B27: =IFERROR(__xludf.DUMMYFUNCTION("""COMPUTED_VALUE"""),0.0) -> 0 | C27: =IFERROR(__xludf.DUMMYFUNCTION("""COMPUTED_VALUE"""),130.0) -> 130 | D27: =IFERROR(__xludf.DUMMYFUNCTION("""COMPUTED_VALUE"""),130.0) -> 130
A28: =IFERROR(__xludf.DUMMYFUNCTION("""COMPUTED_VALUE"""),48618.0) -> 48618 | B28: =IFERROR(__xludf.DUMMYFUNCTION("""COMPUTED_VALUE"""),1.0) -> 1 | C28: =IFERROR(__xludf.DUMMYFUNCTION("""COMPUTED_VALUE"""),84.0) -> 84 | D28: =IFERROR(__xludf.DUMMYFUNCTION("""COMPUTED_VALUE"""),84.0) -> 84
A29: =IFERROR(__xludf.DUMMYFUNCTION("""COMPUTED_VALUE"""),93037.0) -> 93037 | B29: =IFERROR(__xludf.DUMMYFUNCTION("""COMPUTED_VALUE"""),0.0) -> 0 | C29: =IFERROR(__xludf.DUMMYFUNCTION("""COMPUTED_VALUE"""),604.0) -> 604 | D29: =IFERROR(__xludf.DUMMYFUNCTION("""COMPUTED_VALUE"""),604.0) -> 604
A30: =IFERROR(__xludf.DUMMYFUNCTION("""COMPUTED_VALUE"""),126984.0) -> 126984 | B30: =IFERROR(__xludf.DUMMYFUNCTION("""COMPUTED_VALUE"""),0.0) -> 0 | C30: =IFERROR(__xludf.DUMMYFUNCTION("""COMPUTED_VALUE"""),26.0) -> 26 | D30: =IFERROR(__xludf.DUMMYFUNCTION("""COMPUTED_VALUE"""),6.0) -> 6
A31: =IFERROR(__xludf.DUMMYFUNCTION("""COMPUTED_VALUE"""),47393.0) -> 47393 | B31: =IFERROR(__xludf.DUMMYFUNCTION("""COMPUTED_VALUE"""),0.0) -> 0 | C31: =IFERROR(__xludf.DUMMYFUNCTION("""COMPUTED_VALUE"""),982.0) -> 982 | D31: =IFERROR(__xludf.DUMMYFUNCTION("""COMPUTED_VALUE"""),609.0) -> 609
A32: =IFERROR(__xludf.DUMMYFUNCTION("""COMPUTED_VALUE"""),128214.0) -> 128214 | B32: =IFERROR(__xludf.DUMMYFUNCTION("""COMPUTED_VALUE"""),0.0) -> 0 | C32: =IFERROR(__xludf.DUMMYFUNCTION("""COMPUTED_VALUE"""),79.0) -> 79 | D32: =IFERROR(__xludf.DUMMYFUNCTION("""COMPUTED_VALUE"""),79.0) -> 79
A33: =IFERROR(__xludf.DUMMYFUNCTION("""COMPUTED_VALUE"""),83802.0) -> 83802 | B33: =IFERROR(__xludf.DUMMYFUNCTION("""COMPUTED_VALUE"""),0.0) -> 0 | C33: =IFERROR(__xludf.DUMMYFUNCTION("""COMPUTED_VALUE"""),31.0) -> 31 | D33: =IFERROR(__xludf.DUMMYFUNCTION("""COMPUTED_VALUE"""),23.0) -> 23
A34: =IFERROR(__xludf.DUMMYFUNCTION("""COMPUTED_VALUE"""),48625.0) -> 48625 | B34: =IFERROR(__xludf.DUMMYFUNCTION("""COMPUTED_VALUE"""),1.0) -> 1 | C34: =IFERROR(__xludf.DUMMYFUNCTION("""COMPUTED_VALUE"""),96.0) -> 96 | D34: =IFERROR(__xludf.DUMMYFUNCTION("""COMPUTED_VALUE"""),96.0) -> 96
A35: =IFERROR(__xludf.DUMMYFUNCTION("""COMPUTED_VALUE"""),83602.0) -> 83602 | B35: =IFERROR(__xludf.DUMMYFUNCTION("""COMPUTED_VALUE"""),0.0) -> 0 | C35: =IFERROR(__xludf.DUMMYFUNCTION("""COMPUTED_VALUE"""),79.0) -> 79 | D35: =IFERROR(__xludf.DUMMYFUNCTION("""COMPUTED_VALUE"""),79.0) -> 79
A36: =IFERROR(__xludf.DUMMYFUNCTION("""COMPUTED_VALUE"""),98867.0) -> 98867 | B36: =IFERROR(__xludf.DUMMYFUNCTION("""COMPUTED_VALUE"""),0.0) -> 0 | C36: =IFERROR(__xludf.DUMMYFUNCTION("""COMPUTED_VALUE"""),186.0) -> 186 | D36: =IFERROR(__xludf.DUMMYFUNCTION("""COMPUTED_VALUE"""),186.0) -> 186
A37: =IFERROR(__xludf.DUMMYFUNCTION("""COMPUTED_VALUE"""),127042.0) -> 127042 | B37: =IFERROR(__xludf.DUMMYFUNCTION("""COMPUTED_VALUE"""),0.0) -> 0 | C37: =IFERROR(__xludf.DUMMYFUNCTION("""COMPUTED_VALUE"""),418.0) -> 418 | D37: =IFERROR(__xludf.DUMMYFUNCTION("""COMPUTED_VALUE"""),418.0) -> 418
A38: =IFERROR(__xludf.DUMMYFUNCTION("""COMPUTED_VALUE"""),127241.0) -> 127241 | B38: =IFERROR(__xludf.DUMMYFUNCTION("""COMPUTED_VALUE"""),0.0) -> 0 | C38: =IFERROR(__xludf.DUMMYFUNCTION("""COMPUTED_VALUE"""),98.0) -> 98 | D38: =IFERROR(__xludf.DUMMYFUNCTION("""COMPUTED_VALUE"""),98.0) -> 98
A39: =IFERROR(__xludf.DUMMYFUNCTION("""COMPUTED_VALUE"""),118220.0) -> 118220 | B39: =IFERROR(__xludf.DUMMYFUNCTION("""COMPUTED_VALUE"""),0.0) -> 0 | C39: =IFERROR(__xludf.DUMMYFUNCTION("""COMPUTED_VALUE"""),34.0) -> 34 | D39: =IFERROR(__xludf.DUMMYFUNCTION("""COMPUTED_VALUE"""),34.0) -> 34
A40: =IFERROR(__xludf.DUMMYFUNCTION("""COMPUTED_VALUE"""),128216.0) -> 128216 | B40: =IFERROR(__xludf.DUMMYFUNCTION("""COMPUTED_VALUE"""),0.0) -> 0 | C40: =IFERROR(__xludf.DUMMYFUNCTION("""COMPUTED_VALUE"""),141.0) -> 141 | D40: =IFERROR(__xludf.DUMMYFUNCTION("""COMPUTED_VALUE"""),141.0) -> 141
...

Sheet Product
A1: =IFERROR(__xludf.DUMMYFUNCTION("IMPORTRANGE(""https://docs.google.com/spreadsheets/d/1n4Zg-vRlTZzP5FR21bautORUV5kNU7wGUHO1GM0ql3s/edit"",""product!A:Z"")"),"product_id") -> product_id | B1: =IFERROR(__xludf.DUMMYFUNCTION("""COMPUTED_VALUE"""),"category_1") -> category_1 | C1: =IFERROR(__xludf.DUMMYFUNCTION("""COMPUTED_VALUE"""),"category_2") -> category_2 | D1: =IFERROR(__xludf.DUMMYFUNCTION("""COMPUTED_VALUE"""),"category_3") -> category_3 | E1: =IFERROR(__xludf.DUMMYFUNCTION("""COMPUTED_VALUE"""),"pp_cat") -> pp_cat
A2: =IFERROR(__xludf.DUMMYFUNCTION("""COMPUTED_VALUE"""),112463.0) -> 112463 | B2: =IFERROR(__xludf.DUMMYFUNCTION("""COMPUTED_VALUE"""),"Fiction") -> Fiction | C2: =IFERROR(__xludf.DUMMYFUNCTION("""COMPUTED_VALUE"""),"Literary Fiction") -> Literary Fiction | D2: =IFERROR(__xludf.DUMMYFUNCTION("""COMPUTED_VALUE"""),"Blue Oak Publishing") -> Blue Oak Publishing | E2: =IFERROR(__xludf.DUMMYFUNCTION("""COMPUTED_VALUE"""),4.1) -> 4.1
A3: =IFERROR(__xludf.DUMMYFUNCTION("""COMPUTED_VALUE"""),112481.0) -> 112481 | B3: =IFERROR(__xludf.DUMMYFUNCTION("""COMPUTED_VALUE"""),"Fiction") -> Fiction | C3: =IFERROR(__xludf.DUMMYFUNCTION("""COMPUTED_VALUE"""),"Literary Fiction") -> Literary Fiction | D3: =IFERROR(__xludf.DUMMYFUNCTION("""COMPUTED_VALUE"""),"Blue Oak Publishing") -> Blue Oak Publishing | E3: =IFERROR(__xludf.DUMMYFUNCTION("""COMPUTED_VALUE"""),5.86) -> 5.86
A4: =IFERROR(__xludf.DUMMYFUNCTION("""COMPUTED_VALUE"""),13346.0) -> 13346 | B4: =IFERROR(__xludf.DUMMYFUNCTION("""COMPUTED_VALUE"""),"Fiction") -> Fiction | C4: =IFERROR(__xludf.DUMMYFUNCTION("""COMPUTED_VALUE"""),"Literary Fiction") -> Literary Fiction | D4: =IFERROR(__xludf.DUMMYFUNCTION("""COMPUTED_VALUE"""),"Blue Oak Publishing") -> Blue Oak Publishing | E4: =IFERROR(__xludf.DUMMYFUNCTION("""COMPUTED_VALUE"""),2.16) -> 2.16
A5: =IFERROR(__xludf.DUMMYFUNCTION("""COMPUTED_VALUE"""),112454.0) -> 112454 | B5: =IFERROR(__xludf.DUMMYFUNCTION("""COMPUTED_VALUE"""),"Fiction") -> Fiction | C5: =IFERROR(__xludf.DUMMYFUNCTION("""COMPUTED_VALUE"""),"Literary Fiction") -> Literary Fiction | D5: =IFERROR(__xludf.DUMMYFUNCTION("""COMPUTED_VALUE"""),"Blue Oak Publishing") -> Blue Oak Publishing | E5: =IFERROR(__xludf.DUMMYFUNCTION("""COMPUTED_VALUE"""),0.93) -> 0.93
A6: =IFERROR(__xludf.DUMMYFUNCTION("""COMPUTED_VALUE"""),112461.0) -> 112461 | B6: =IFERROR(__xludf.DUMMYFUNCTION("""COMPUTED_VALUE"""),"Fiction") -> Fiction | C6: =IFERROR(__xludf.DUMMYFUNCTION("""COMPUTED_VALUE"""),"Literary Fiction") -> Literary Fiction | D6: =IFERROR(__xludf.DUMMYFUNCTION("""COMPUTED_VALUE"""),"Blue Oak Publishing") -> Blue Oak Publishing | E6: =IFERROR(__xludf.DUMMYFUNCTION("""COMPUTED_VALUE"""),1.07) -> 1.07
A7: =IFERROR(__xludf.DUMMYFUNCTION("""COMPUTED_VALUE"""),106532.0) -> 106532 | B7: =IFERROR(__xludf.DUMMYFUNCTION("""COMPUTED_VALUE"""),"Fiction") -> Fiction | C7: =IFERROR(__xludf.DUMMYFUNCTION("""COMPUTED_VALUE"""),"Literary Fiction") -> Literary Fiction | D7: =IFERROR(__xludf.DUMMYFUNCTION("""COMPUTED_VALUE"""),"Silver Leaf Press") -> Silver Leaf Press | E7: =IFERROR(__xludf.DUMMYFUNCTION("""COMPUTED_VALUE"""),8.9) -> 8.9
A8: =IFERROR(__xludf.DUMMYFUNCTION("""COMPUTED_VALUE"""),121135.0) -> 121135 | B8: =IFERROR(__xludf.DUMMYFUNCTION("""COMPUTED_VALUE"""),"Fiction") -> Fiction | C8: =IFERROR(__xludf.DUMMYFUNCTION("""COMPUTED_VALUE"""),"Literary Fiction") -> Literary Fiction | D8: =IFERROR(__xludf.DUMMYFUNCTION("""COMPUTED_VALUE"""),"Silver Leaf Press") -> Silver Leaf Press | E8: =IFERROR(__xludf.DUMMYFUNCTION("""COMPUTED_VALUE"""),8.84) -> 8.84
A9: =IFERROR(__xludf.DUMMYFUNCTION("""COMPUTED_VALUE"""),128362.0) -> 128362 | B9: =IFERROR(__xludf.DUMMYFUNCTION("""COMPUTED_VALUE"""),"History") -> History | C9: =IFERROR(__xludf.DUMMYFUNCTION("""COMPUTED_VALUE"""),"Mystery") -> Mystery | D9: =IFERROR(__xludf.DUMMYFUNCTION("""COMPUTED_VALUE"""),"Northbridge Books") -> Northbridge Books | E9: =IFERROR(__xludf.DUMMYFUNCTION("""COMPUTED_VALUE"""),4.89) -> 4.89
A10: =IFERROR(__xludf.DUMMYFUNCTION("""COMPUTED_VALUE"""),71200.0) -> 71200 | B10: =IFERROR(__xludf.DUMMYFUNCTION("""COMPUTED_VALUE"""),"History") -> History | C10: =IFERROR(__xludf.DUMMYFUNCTION("""COMPUTED_VALUE"""),"Mystery") -> Mystery | D10: =IFERROR(__xludf.DUMMYFUNCTION("""COMPUTED_VALUE"""),"Riverstone Publishing") -> Riverstone Publishing | E10: =IFERROR(__xludf.DUMMYFUNCTION("""COMPUTED_VALUE"""),1.94) -> 1.94
A11: =IFERROR(__xludf.DUMMYFUNCTION("""COMPUTED_VALUE"""),19812.0) -> 19812 | B11: =IFERROR(__xludf.DUMMYFUNCTION("""COMPUTED_VALUE"""),"History") -> History | C11: =IFERROR(__xludf.DUMMYFUNCTION("""COMPUTED_VALUE"""),"Mystery") -> Mystery | D11: =IFERROR(__xludf.DUMMYFUNCTION("""COMPUTED_VALUE"""),"Riverstone Publishing") -> Riverstone Publishing | E11: =IFERROR(__xludf.DUMMYFUNCTION("""COMPUTED_VALUE"""),1.77) -> 1.77
A12: =IFERROR(__xludf.DUMMYFUNCTION("""COMPUTED_VALUE"""),122259.0) -> 122259 | B12: =IFERROR(__xludf.DUMMYFUNCTION("""COMPUTED_VALUE"""),"History") -> History | C12: =IFERROR(__xludf.DUMMYFUNCTION("""COMPUTED_VALUE"""),"Mystery") -> Mystery | D12: =IFERROR(__xludf.DUMMYFUNCTION("""COMPUTED_VALUE"""),"Golden Quill Press") -> Golden Quill Press | E12: =IFERROR(__xludf.DUMMYFUNCTION("""COMPUTED_VALUE"""),2.88) -> 2.88
A13: =IFERROR(__xludf.DUMMYFUNCTION("""COMPUTED_VALUE"""),199526.0) -> 199526 | B13: =IFERROR(__xludf.DUMMYFUNCTION("""COMPUTED_VALUE"""),"History") -> History | C13: =IFERROR(__xludf.DUMMYFUNCTION("""COMPUTED_VALUE"""),"Mystery") -> Mystery | D13: =IFERROR(__xludf.DUMMYFUNCTION("""COMPUTED_VALUE"""),"Golden Quill Press") -> Golden Quill Press | E13: =IFERROR(__xludf.DUMMYFUNCTION("""COMPUTED_VALUE"""),1.83) -> 1.83
A14: =IFERROR(__xludf.DUMMYFUNCTION("""COMPUTED_VALUE"""),140581.0) -> 140581 | B14: =IFERROR(__xludf.DUMMYFUNCTION("""COMPUTED_VALUE"""),"History") -> History | C14: =IFERROR(__xludf.DUMMYFUNCTION("""COMPUTED_VALUE"""),"Mystery") -> Mystery | D14: =IFERROR(__xludf.DUMMYFUNCTION("""COMPUTED_VALUE"""),"Golden Quill Press") -> Golden Quill Press | E14: =IFERROR(__xludf.DUMMYFUNCTION("""COMPUTED_VALUE"""),4.04) -> 4.04
A15: =IFERROR(__xludf.DUMMYFUNCTION("""COMPUTED_VALUE"""),118383.0) -> 118383 | B15: =IFERROR(__xludf.DUMMYFUNCTION("""COMPUTED_VALUE"""),"History") -> History | C15: =IFERROR(__xludf.DUMMYFUNCTION("""COMPUTED_VALUE"""),"Mystery") -> Mystery | D15: =IFERROR(__xludf.DUMMYFUNCTION("""COMPUTED_VALUE"""),"Golden Quill Press") -> Golden Quill Press | E15: =IFERROR(__xludf.DUMMYFUNCTION("""COMPUTED_VALUE"""),1.5) -> 1.5
A16: =IFERROR(__xludf.DUMMYFUNCTION("""COMPUTED_VALUE"""),122262.0) -> 122262 | B16: =IFERROR(__xludf.DUMMYFUNCTION("""COMPUTED_VALUE"""),"History") -> History | C16: =IFERROR(__xludf.DUMMYFUNCTION("""COMPUTED_VALUE"""),"Mystery") -> Mystery | D16: =IFERROR(__xludf.DUMMYFUNCTION("""COMPUTED_VALUE"""),"Golden Quill Press") -> Golden Quill Press | E16: =IFERROR(__xludf.DUMMYFUNCTION("""COMPUTED_VALUE"""),2.65) -> 2.65
A17: =IFERROR(__xludf.DUMMYFUNCTION("""COMPUTED_VALUE"""),141879.0) -> 141879 | B17: =IFERROR(__xludf.DUMMYFUNCTION("""COMPUTED_VALUE"""),"History") -> History | C17: =IFERROR(__xludf.DUMMYFUNCTION("""COMPUTED_VALUE"""),"Mystery") -> Mystery | D17: =IFERROR(__xludf.DUMMYFUNCTION("""COMPUTED_VALUE"""),"Golden Quill Press") -> Golden Quill Press | E17: =IFERROR(__xludf.DUMMYFUNCTION("""COMPUTED_VALUE"""),2.04) -> 2.04
A18: =IFERROR(__xludf.DUMMYFUNCTION("""COMPUTED_VALUE"""),19826.0) -> 19826 | B18: =IFERROR(__xludf.DUMMYFUNCTION("""COMPUTED_VALUE"""),"History") -> History | C18: =IFERROR(__xludf.DUMMYFUNCTION("""COMPUTED_VALUE"""),"Thriller") -> Thriller | D18: =IFERROR(__xludf.DUMMYFUNCTION("""COMPUTED_VALUE"""),"Harbor Light Books") -> Harbor Light Books | E18: =IFERROR(__xludf.DUMMYFUNCTION("""COMPUTED_VALUE"""),2.88) -> 2.88
A19: =IFERROR(__xludf.DUMMYFUNCTION("""COMPUTED_VALUE"""),93039.0) -> 93039 | B19: =IFERROR(__xludf.DUMMYFUNCTION("""COMPUTED_VALUE"""),"History") -> History | C19: =IFERROR(__xludf.DUMMYFUNCTION("""COMPUTED_VALUE"""),"Thriller") -> Thriller | D19: =IFERROR(__xludf.DUMMYFUNCTION("""COMPUTED_VALUE"""),"Harbor Light Books") -> Harbor Light Books | E19: =IFERROR(__xludf.DUMMYFUNCTION("""COMPUTED_VALUE"""),3.23) -> 3.23
A20: =IFERROR(__xludf.DUMMYFUNCTION("""COMPUTED_VALUE"""),128213.0) -> 128213 | B20: =IFERROR(__xludf.DUMMYFUNCTION("""COMPUTED_VALUE"""),"History") -> History | C20: =IFERROR(__xludf.DUMMYFUNCTION("""COMPUTED_VALUE"""),"Thriller") -> Thriller | D20: =IFERROR(__xludf.DUMMYFUNCTION("""COMPUTED_VALUE"""),"Harbor Light Books") -> Harbor Light Books | E20: =IFERROR(__xludf.DUMMYFUNCTION("""COMPUTED_VALUE"""),4.72) -> 4.72
A21: =IFERROR(__xludf.DUMMYFUNCTION("""COMPUTED_VALUE"""),83797.0) -> 83797 | B21: =IFERROR(__xludf.DUMMYFUNCTION("""COMPUTED_VALUE"""),"History") -> History | C21: =IFERROR(__xludf.DUMMYFUNCTION("""COMPUTED_VALUE"""),"Thriller") -> Thriller | D21: =IFERROR(__xludf.DUMMYFUNCTION("""COMPUTED_VALUE"""),"Harbor Light Books") -> Harbor Light Books | E21: =IFERROR(__xludf.DUMMYFUNCTION("""COMPUTED_VALUE"""),6.05) -> 6.05
A22: =IFERROR(__xludf.DUMMYFUNCTION("""COMPUTED_VALUE"""),19831.0) -> 19831 | B22: =IFERROR(__xludf.DUMMYFUNCTION("""COMPUTED_VALUE"""),"History") -> History | C22: =IFERROR(__xludf.DUMMYFUNCTION("""COMPUTED_VALUE"""),"Thriller") -> Thriller | D22: =IFERROR(__xludf.DUMMYFUNCTION("""COMPUTED_VALUE"""),"Harbor Light Books") -> Harbor Light Books | E22: =IFERROR(__xludf.DUMMYFUNCTION("""COMPUTED_VALUE"""),3.86) -> 3.86
A23: =IFERROR(__xludf.DUMMYFUNCTION("""COMPUTED_VALUE"""),93025.0) -> 93025 | B23: =IFERROR(__xludf.DUMMYFUNCTION("""COMPUTED_VALUE"""),"History") -> History | C23: =IFERROR(__xludf.DUMMYFUNCTION("""COMPUTED_VALUE"""),"Thriller") -> Thriller | D23: =IFERROR(__xludf.DUMMYFUNCTION("""COMPUTED_VALUE"""),"Harbor Light Books") -> Harbor Light Books | E23: =IFERROR(__xludf.DUMMYFUNCTION("""COMPUTED_VALUE"""),2.31) -> 2.31
A24: =IFERROR(__xludf.DUMMYFUNCTION("""COMPUTED_VALUE"""),81624.0) -> 81624 | B24: =IFERROR(__xludf.DUMMYFUNCTION("""COMPUTED_VALUE"""),"History") -> History | C24: =IFERROR(__xludf.DUMMYFUNCTION("""COMPUTED_VALUE"""),"Thriller") -> Thriller | D24: =IFERROR(__xludf.DUMMYFUNCTION("""COMPUTED_VALUE"""),"Harbor Light Books") -> Harbor Light Books | E24: =IFERROR(__xludf.DUMMYFUNCTION("""COMPUTED_VALUE"""),7.35) -> 7.35
A25: =IFERROR(__xludf.DUMMYFUNCTION("""COMPUTED_VALUE"""),92913.0) -> 92913 | B25: =IFERROR(__xludf.DUMMYFUNCTION("""COMPUTED_VALUE"""),"History") -> History | C25: =IFERROR(__xludf.DUMMYFUNCTION("""COMPUTED_VALUE"""),"Thriller") -> Thriller | D25: =IFERROR(__xludf.DUMMYFUNCTION("""COMPUTED_VALUE"""),"Harbor Light Books") -> Harbor Light Books | E25: =IFERROR(__xludf.DUMMYFUNCTION("""COMPUTED_VALUE"""),7.02) -> 7.02
A26: =IFERROR(__xludf.DUMMYFUNCTION("""COMPUTED_VALUE"""),126983.0) -> 126983 | B26: =IFERROR(__xludf.DUMMYFUNCTION("""COMPUTED_VALUE"""),"History") -> History | C26: =IFERROR(__xludf.DUMMYFUNCTION("""COMPUTED_VALUE"""),"Thriller") -> Thriller | D26: =IFERROR(__xludf.DUMMYFUNCTION("""COMPUTED_VALUE"""),"Harbor Light Books") -> Harbor Light Books | E26: =IFERROR(__xludf.DUMMYFUNCTION("""COMPUTED_VALUE"""),2.69) -> 2.69
A27: =IFERROR(__xludf.DUMMYFUNCTION("""COMPUTED_VALUE"""),118226.0) -> 118226 | B27: =IFERROR(__xludf.DUMMYFUNCTION("""COMPUTED_VALUE"""),"History") -> History | C27: =IFERROR(__xludf.DUMMYFUNCTION("""COMPUTED_VALUE"""),"Thriller") -> Thriller | D27: =IFERROR(__xludf.DUMMYFUNCTION("""COMPUTED_VALUE"""),"Harbor Light Books") -> Harbor Light Books | E27: =IFERROR(__xludf.DUMMYFUNCTION("""COMPUTED_VALUE"""),1.89) -> 1.89
A28: =IFERROR(__xludf.DUMMYFUNCTION("""COMPUTED_VALUE"""),48618.0) -> 48618 | B28: =IFERROR(__xludf.DUMMYFUNCTION("""COMPUTED_VALUE"""),"History") -> History | C28: =IFERROR(__xludf.DUMMYFUNCTION("""COMPUTED_VALUE"""),"Thriller") -> Thriller | D28: =IFERROR(__xludf.DUMMYFUNCTION("""COMPUTED_VALUE"""),"Harbor Light Books") -> Harbor Light Books | E28: =IFERROR(__xludf.DUMMYFUNCTION("""COMPUTED_VALUE"""),2.39) -> 2.39
A29: =IFERROR(__xludf.DUMMYFUNCTION("""COMPUTED_VALUE"""),93037.0) -> 93037 | B29: =IFERROR(__xludf.DUMMYFUNCTION("""COMPUTED_VALUE"""),"History") -> History | C29: =IFERROR(__xludf.DUMMYFUNCTION("""COMPUTED_VALUE"""),"Thriller") -> Thriller | D29: =IFERROR(__xludf.DUMMYFUNCTION("""COMPUTED_VALUE"""),"Harbor Light Books") -> Harbor Light Books | E29: =IFERROR(__xludf.DUMMYFUNCTION("""COMPUTED_VALUE"""),2.93) -> 2.93
A30: =IFERROR(__xludf.DUMMYFUNCTION("""COMPUTED_VALUE"""),126984.0) -> 126984 | B30: =IFERROR(__xludf.DUMMYFUNCTION("""COMPUTED_VALUE"""),"History") -> History | C30: =IFERROR(__xludf.DUMMYFUNCTION("""COMPUTED_VALUE"""),"Thriller") -> Thriller | D30: =IFERROR(__xludf.DUMMYFUNCTION("""COMPUTED_VALUE"""),"Harbor Light Books") -> Harbor Light Books | E30: =IFERROR(__xludf.DUMMYFUNCTION("""COMPUTED_VALUE"""),2.02) -> 2.02
A31: =IFERROR(__xludf.DUMMYFUNCTION("""COMPUTED_VALUE"""),47393.0) -> 47393 | B31: =IFERROR(__xludf.DUMMYFUNCTION("""COMPUTED_VALUE"""),"History") -> History | C31: =IFERROR(__xludf.DUMMYFUNCTION("""COMPUTED_VALUE"""),"Thriller") -> Thriller | D31: =IFERROR(__xludf.DUMMYFUNCTION("""COMPUTED_VALUE"""),"Harbor Light Books") -> Harbor Light Books | E31: =IFERROR(__xludf.DUMMYFUNCTION("""COMPUTED_VALUE"""),2.66) -> 2.66
A32: =IFERROR(__xludf.DUMMYFUNCTION("""COMPUTED_VALUE"""),128214.0) -> 128214 | B32: =IFERROR(__xludf.DUMMYFUNCTION("""COMPUTED_VALUE"""),"History") -> History | C32: =IFERROR(__xludf.DUMMYFUNCTION("""COMPUTED_VALUE"""),"Thriller") -> Thriller | D32: =IFERROR(__xludf.DUMMYFUNCTION("""COMPUTED_VALUE"""),"Harbor Light Books") -> Harbor Light Books | E32: =IFERROR(__xludf.DUMMYFUNCTION("""COMPUTED_VALUE"""),4.35) -> 4.35
A33: =IFERROR(__xludf.DUMMYFUNCTION("""COMPUTED_VALUE"""),83802.0) -> 83802 | B33: =IFERROR(__xludf.DUMMYFUNCTION("""COMPUTED_VALUE"""),"History") -> History | C33: =IFERROR(__xludf.DUMMYFUNCTION("""COMPUTED_VALUE"""),"Thriller") -> Thriller | D33: =IFERROR(__xludf.DUMMYFUNCTION("""COMPUTED_VALUE"""),"Harbor Light Books") -> Harbor Light Books | E33: =IFERROR(__xludf.DUMMYFUNCTION("""COMPUTED_VALUE"""),3.33) -> 3.33
A34: =IFERROR(__xludf.DUMMYFUNCTION("""COMPUTED_VALUE"""),48625.0) -> 48625 | B34: =IFERROR(__xludf.DUMMYFUNCTION("""COMPUTED_VALUE"""),"History") -> History | C34: =IFERROR(__xludf.DUMMYFUNCTION("""COMPUTED_VALUE"""),"Thriller") -> Thriller | D34: =IFERROR(__xludf.DUMMYFUNCTION("""COMPUTED_VALUE"""),"Harbor Light Books") -> Harbor Light Books | E34: =IFERROR(__xludf.DUMMYFUNCTION("""COMPUTED_VALUE"""),4.12) -> 4.12
A35: =IFERROR(__xludf.DUMMYFUNCTION("""COMPUTED_VALUE"""),83602.0) -> 83602 | B35: =IFERROR(__xludf.DUMMYFUNCTION("""COMPUTED_VALUE"""),"History") -> History | C35: =IFERROR(__xludf.DUMMYFUNCTION("""COMPUTED_VALUE"""),"Thriller") -> Thriller | D35: =IFERROR(__xludf.DUMMYFUNCTION("""COMPUTED_VALUE"""),"Harbor Light Books") -> Harbor Light Books | E35: =IFERROR(__xludf.DUMMYFUNCTION("""COMPUTED_VALUE"""),12.34) -> 12.34
A36: =IFERROR(__xludf.DUMMYFUNCTION("""COMPUTED_VALUE"""),98867.0) -> 98867 | B36: =IFERROR(__xludf.DUMMYFUNCTION("""COMPUTED_VALUE"""),"History") -> History | C36: =IFERROR(__xludf.DUMMYFUNCTION("""COMPUTED_VALUE"""),"Thriller") -> Thriller | D36: =IFERROR(__xludf.DUMMYFUNCTION("""COMPUTED_VALUE"""),"Ironwood Publishing") -> Ironwood Publishing | E36: =IFERROR(__xludf.DUMMYFUNCTION("""COMPUTED_VALUE"""),4.2) -> 4.2
A37: =IFERROR(__xludf.DUMMYFUNCTION("""COMPUTED_VALUE"""),127042.0) -> 127042 | B37: =IFERROR(__xludf.DUMMYFUNCTION("""COMPUTED_VALUE"""),"History") -> History | C37: =IFERROR(__xludf.DUMMYFUNCTION("""COMPUTED_VALUE"""),"Thriller") -> Thriller | D37: =IFERROR(__xludf.DUMMYFUNCTION("""COMPUTED_VALUE"""),"Ironwood Publishing") -> Ironwood Publishing | E37: =IFERROR(__xludf.DUMMYFUNCTION("""COMPUTED_VALUE"""),4.05) -> 4.05
A38: =IFERROR(__xludf.DUMMYFUNCTION("""COMPUTED_VALUE"""),127241.0) -> 127241 | B38: =IFERROR(__xludf.DUMMYFUNCTION("""COMPUTED_VALUE"""),"History") -> History | C38: =IFERROR(__xludf.DUMMYFUNCTION("""COMPUTED_VALUE"""),"Thriller") -> Thriller | D38: =IFERROR(__xludf.DUMMYFUNCTION("""COMPUTED_VALUE"""),"Maple Grove Press") -> Maple Grove Press | E38: =IFERROR(__xludf.DUMMYFUNCTION("""COMPUTED_VALUE"""),12.24) -> 12.24
A39: =IFERROR(__xludf.DUMMYFUNCTION("""COMPUTED_VALUE"""),118220.0) -> 118220 | B39: =IFERROR(__xludf.DUMMYFUNCTION("""COMPUTED_VALUE"""),"History") -> History | C39: =IFERROR(__xludf.DUMMYFUNCTION("""COMPUTED_VALUE"""),"Thriller") -> Thriller | D39: =IFERROR(__xludf.DUMMYFUNCTION("""COMPUTED_VALUE"""),"Maple Grove Press") -> Maple Grove Press | E39: =IFERROR(__xludf.DUMMYFUNCTION("""COMPUTED_VALUE"""),8.54) -> 8.54
A40: =IFERROR(__xludf.DUMMYFUNCTION("""COMPUTED_VALUE"""),128216.0) -> 128216 | B40: =IFERROR(__xludf.DUMMYFUNCTION("""COMPUTED_VALUE"""),"History") -> History | C40: =IFERROR(__xludf.DUMMYFUNCTION("""COMPUTED_VALUE"""),"Thriller") -> Thriller | D40: =IFERROR(__xludf.DUMMYFUNCTION("""COMPUTED_VALUE"""),"Maple Grove Press") -> Maple Grove Press | E40: =IFERROR(__xludf.DUMMYFUNCTION("""COMPUTED_VALUE"""),12.08) -> 12.08
...

Sheet Exploration >>

Sheet Explo_Stock
A1: =IFERROR(__xludf.DUMMYFUNCTION("IMPORTRANGE(""https://docs.google.com/spreadsheets/d/1yOpZnyZ5ouw2C51zn4VNSNmNNrizgIE5YAyno7ltBiE/edit"",""stock!A:d"")"),"product_id") -> product_id | B1: =IFERROR(__xludf.DUMMYFUNCTION("""COMPUTED_VALUE"""),"new") -> new | C1: =IFERROR(__xludf.DUMMYFUNCTION("""COMPUTED_VALUE"""),"forecast_stock") -> forecast_stock | D1: =IFERROR(__xludf.DUMMYFUNCTION("""COMPUTED_VALUE"""),"stock") -> stock | E1: category_1 | F1: category_2 | G1: category_3 | H1: pp_cat | I1: product_name | J1: stok_value | K1: in_stock
A2: =IFERROR(__xludf.DUMMYFUNCTION("""COMPUTED_VALUE"""),112463.0) -> 112463 | B2: =IFERROR(__xludf.DUMMYFUNCTION("""COMPUTED_VALUE"""),0.0) -> 0 | C2: =IFERROR(__xludf.DUMMYFUNCTION("""COMPUTED_VALUE"""),320.0) -> 320 | D2: =IFERROR(__xludf.DUMMYFUNCTION("""COMPUTED_VALUE"""),320.0) -> 320 | E2: {=_xlfn.XLOOKUP(A2,Product!A:A,Product!B:B,"Bulunamadı")} -> Fiction | F2: {=_xlfn.XLOOKUP(A2,Product!A:A,Product!C:C,"Bulunamadı")} -> Literary Fiction | G2: {=_xlfn.XLOOKUP(A3,Product!A:A,Product!D:D,"Bulunamadı")} -> Blue Oak Publishing | H2: {=_xlfn.XLOOKUP(A4,Product!A:A,Product!E:E,"Bulunamadı")} -> 2.16 | I2: =A2&" - "&E2&" - "&F2 -> 112463 - Fiction - Literary Fiction | J2: =D2*H2 -> 691.2 | K2: =IF(D2>0,1,0) -> 1
A3: =IFERROR(__xludf.DUMMYFUNCTION("""COMPUTED_VALUE"""),112481.0) -> 112481 | B3: =IFERROR(__xludf.DUMMYFUNCTION("""COMPUTED_VALUE"""),0.0) -> 0 | C3: =IFERROR(__xludf.DUMMYFUNCTION("""COMPUTED_VALUE"""),0.0) -> 0 | D3: =IFERROR(__xludf.DUMMYFUNCTION("""COMPUTED_VALUE"""),0.0) -> 0 | E3: {=_xlfn.XLOOKUP(A3,Product!A:A,Product!B:B,"Bulunamadı")} -> Fiction | F3: {=_xlfn.XLOOKUP(A3,Product!A:A,Product!C:C,"Bulunamadı")} -> Literary Fiction | G3: {=_xlfn.XLOOKUP(A4,Product!A:A,Product!D:D,"Bulunamadı")} -> Blue Oak Publishing | H3: {=_xlfn.XLOOKUP(A5,Product!A:A,Product!E:E,"Bulunamadı")} -> 0.93 | I3: =A3&" - "&E3&" - "&F3 -> 112481 - Fiction - Literary Fiction | J3: =D3*H3 -> 0 | K3: =IF(D3>0,1,0) -> 0
A4: =IFERROR(__xludf.DUMMYFUNCTION("""COMPUTED_VALUE"""),13346.0) -> 13346 | B4: =IFERROR(__xludf.DUMMYFUNCTION("""COMPUTED_VALUE"""),1.0) -> 1 | C4: =IFERROR(__xludf.DUMMYFUNCTION("""COMPUTED_VALUE"""),100.0) -> 100 | D4: =IFERROR(__xludf.DUMMYFUNCTION("""COMPUTED_VALUE"""),100.0) -> 100 | E4: {=_xlfn.XLOOKUP(A4,Product!A:A,Product!B:B,"Bulunamadı")} -> Fiction | F4: {=_xlfn.XLOOKUP(A4,Product!A:A,Product!C:C,"Bulunamadı")} -> Literary Fiction | G4: {=_xlfn.XLOOKUP(A5,Product!A:A,Product!D:D,"Bulunamadı")} -> Blue Oak Publishing | H4: {=_xlfn.XLOOKUP(A6,Product!A:A,Product!E:E,"Bulunamadı")} -> 1.07 | I4: =A4&" - "&E4&" - "&F4 -> 13346 - Fiction - Literary Fiction | J4: =D4*H4 -> 107 | K4: =IF(D4>0,1,0) -> 1
A5: =IFERROR(__xludf.DUMMYFUNCTION("""COMPUTED_VALUE"""),112454.0) -> 112454 | B5: =IFERROR(__xludf.DUMMYFUNCTION("""COMPUTED_VALUE"""),0.0) -> 0 | C5: =IFERROR(__xludf.DUMMYFUNCTION("""COMPUTED_VALUE"""),277.0) -> 277 | D5: =IFERROR(__xludf.DUMMYFUNCTION("""COMPUTED_VALUE"""),268.0) -> 268 | E5: {=_xlfn.XLOOKUP(A5,Product!A:A,Product!B:B,"Bulunamadı")} -> Fiction | F5: {=_xlfn.XLOOKUP(A5,Product!A:A,Product!C:C,"Bulunamadı")} -> Literary Fiction | G5: {=_xlfn.XLOOKUP(A6,Product!A:A,Product!D:D,"Bulunamadı")} -> Blue Oak Publishing | H5: {=_xlfn.XLOOKUP(A7,Product!A:A,Product!E:E,"Bulunamadı")} -> 8.9 | I5: =A5&" - "&E5&" - "&F5 -> 112454 - Fiction - Literary Fiction | J5: =D5*H5 -> 2385.2 | K5: =IF(D5>0,1,0) -> 1
A6: =IFERROR(__xludf.DUMMYFUNCTION("""COMPUTED_VALUE"""),112461.0) -> 112461 | B6: =IFERROR(__xludf.DUMMYFUNCTION("""COMPUTED_VALUE"""),0.0) -> 0 | C6: =IFERROR(__xludf.DUMMYFUNCTION("""COMPUTED_VALUE"""),971.0) -> 971 | D6: =IFERROR(__xludf.DUMMYFUNCTION("""COMPUTED_VALUE"""),472.0) -> 472 | E6: {=_xlfn.XLOOKUP(A6,Product!A:A,Product!B:B,"Bulunamadı")} -> Fiction | F6: {=_xlfn.XLOOKUP(A6,Product!A:A,Product!C:C,"Bulunamadı")} -> Literary Fiction | G6: {=_xlfn.XLOOKUP(A7,Product!A:A,Product!D:D,"Bulunamadı")} -> Silver Leaf Press | H6: {=_xlfn.XLOOKUP(A8,Product!A:A,Product!E:E,"Bulunamadı")} -> 8.84 | I6: =A6&" - "&E6&" - "&F6 -> 112461 - Fiction - Literary Fiction | J6: =D6*H6 -> 4172.48 | K6: =IF(D6>0,1,0) -> 1
A7: =IFERROR(__xludf.DUMMYFUNCTION("""COMPUTED_VALUE"""),106532.0) -> 106532 | B7: =IFERROR(__xludf.DUMMYFUNCTION("""COMPUTED_VALUE"""),0.0) -> 0 | C7: =IFERROR(__xludf.DUMMYFUNCTION("""COMPUTED_VALUE"""),63.0) -> 63 | D7: =IFERROR(__xludf.DUMMYFUNCTION("""COMPUTED_VALUE"""),63.0) -> 63 | E7: {=_xlfn.XLOOKUP(A7,Product!A:A,Product!B:B,"Bulunamadı")} -> Fiction | F7: {=_xlfn.XLOOKUP(A7,Product!A:A,Product!C:C,"Bulunamadı")} -> Literary Fiction | G7: {=_xlfn.XLOOKUP(A8,Product!A:A,Product!D:D,"Bulunamadı")} -> Silver Leaf Press | H7: {=_xlfn.XLOOKUP(A9,Product!A:A,Product!E:E,"Bulunamadı")} -> 4.89 | I7: =A7&" - "&E7&" - "&F7 -> 106532 - Fiction - Literary Fiction | J7: =D7*H7 -> 308.07 | K7: =IF(D7>0,1,0) -> 1
A8: =IFERROR(__xludf.DUMMYFUNCTION("""COMPUTED_VALUE"""),121135.0) -> 121135 | B8: =IFERROR(__xludf.DUMMYFUNCTION("""COMPUTED_VALUE"""),1.0) -> 1 | C8: =IFERROR(__xludf.DUMMYFUNCTION("""COMPUTED_VALUE"""),40.0) -> 40 | D8: =IFERROR(__xludf.DUMMYFUNCTION("""COMPUTED_VALUE"""),33.0) -> 33 | E8: {=_xlfn.XLOOKUP(A8,Product!A:A,Product!B:B,"Bulunamadı")} -> Fiction | F8: {=_xlfn.XLOOKUP(A8,Product!A:A,Product!C:C,"Bulunamadı")} -> Literary Fiction | G8: {=_xlfn.XLOOKUP(A9,Product!A:A,Product!D:D,"Bulunamadı")} -> Northbridge Books | H8: {=_xlfn.XLOOKUP(A10,Product!A:A,Product!E:E,"Bulunamadı")} -> 1.94 | I8: =A8&" - "&E8&" - "&F8 -> 121135 - Fiction - Literary Fiction | J8: =D8*H8 -> 64.02 | K8: =IF(D8>0,1,0) -> 1
A9: =IFERROR(__xludf.DUMMYFUNCTION("""COMPUTED_VALUE"""),128362.0) -> 128362 | B9: =IFERROR(__xludf.DUMMYFUNCTION("""COMPUTED_VALUE"""),1.0) -> 1 | C9: =IFERROR(__xludf.DUMMYFUNCTION("""COMPUTED_VALUE"""),269.0) -> 269 | D9: =IFERROR(__xludf.DUMMYFUNCTION("""COMPUTED_VALUE"""),104.0) -> 104 | E9: {=_xlfn.XLOOKUP(A9,Product!A:A,Product!B:B,"Bulunamadı")} -> History | F9: {=_xlfn.XLOOKUP(A9,Product!A:A,Product!C:C,"Bulunamadı")} -> Mystery | G9: {=_xlfn.XLOOKUP(A10,Product!A:A,Product!D:D,"Bulunamadı")} -> Riverstone Publishing | H9: {=_xlfn.XLOOKUP(A11,Product!A:A,Product!E:E,"Bulunamadı")} -> 1.77 | I9: =A9&" - "&E9&" - "&F9 -> 128362 - History - Mystery | J9: =D9*H9 -> 184.08 | K9: =IF(D9>0,1,0) -> 1
A10: =IFERROR(__xludf.DUMMYFUNCTION("""COMPUTED_VALUE"""),71200.0) -> 71200 | B10: =IFERROR(__xludf.DUMMYFUNCTION("""COMPUTED_VALUE"""),0.0) -> 0 | C10: =IFERROR(__xludf.DUMMYFUNCTION("""COMPUTED_VALUE"""),164.0) -> 164 | D10: =IFERROR(__xludf.DUMMYFUNCTION("""COMPUTED_VALUE"""),152.0) -> 152 | E10: {=_xlfn.XLOOKUP(A10,Product!A:A,Product!B:B,"Bulunamadı")} -> History | F10: {=_xlfn.XLOOKUP(A10,Product!A:A,Product!C:C,"Bulunamadı")} -> Mystery | G10: {=_xlfn.XLOOKUP(A11,Product!A:A,Product!D:D,"Bulunamadı")} -> Riverstone Publishing | H10: {=_xlfn.XLOOKUP(A12,Product!A:A,Product!E:E,"Bulunamadı")} -> 2.88 | I10: =A10&" - "&E10&" - "&F10 -> 71200 - History - Mystery | J10: =D10*H10 -> 437.76 | K10: =IF(D10>0,1,0) -> 1
A11: =IFERROR(__xludf.DUMMYFUNCTION("""COMPUTED_VALUE"""),19812.0) -> 19812 | B11: =IFERROR(__xludf.DUMMYFUNCTION("""COMPUTED_VALUE"""),0.0) -> 0 | C11: =IFERROR(__xludf.DUMMYFUNCTION("""COMPUTED_VALUE"""),489.0) -> 489 | D11: =IFERROR(__xludf.DUMMYFUNCTION("""COMPUTED_VALUE"""),393.0) -> 393 | E11: {=_xlfn.XLOOKUP(A11,Product!A:A,Product!B:B,"Bulunamadı")} -> History | F11: {=_xlfn.XLOOKUP(A11,Product!A:A,Product!C:C,"Bulunamadı")} -> Mystery | G11: {=_xlfn.XLOOKUP(A12,Product!A:A,Product!D:D,"Bulunamadı")} -> Golden Quill Press | H11: {=_xlfn.XLOOKUP(A13,Product!A:A,Product!E:E,"Bulunamadı")} -> 1.83 | I11: =A11&" - "&E11&" - "&F11 -> 19812 - History - Mystery | J11: =D11*H11 -> 719.19 | K11: =IF(D11>0,1,0) -> 1
A12: =IFERROR(__xludf.DUMMYFUNCTION("""COMPUTED_VALUE"""),122259.0) -> 122259 | B12: =IFERROR(__xludf.DUMMYFUNCTION("""COMPUTED_VALUE"""),1.0) -> 1 | C12: =IFERROR(__xludf.DUMMYFUNCTION("""COMPUTED_VALUE"""),104.0) -> 104 | D12: =IFERROR(__xludf.DUMMYFUNCTION("""COMPUTED_VALUE"""),104.0) -> 104 | E12: {=_xlfn.XLOOKUP(A12,Product!A:A,Product!B:B,"Bulunamadı")} -> History | F12: {=_xlfn.XLOOKUP(A12,Product!A:A,Product!C:C,"Bulunamadı")} -> Mystery | G12: {=_xlfn.XLOOKUP(A13,Product!A:A,Product!D:D,"Bulunamadı")} -> Golden Quill Press | H12: {=_xlfn.XLOOKUP(A14,Product!A:A,Product!E:E,"Bulunamadı")} -> 4.04 | I12: =A12&" - "&E12&" - "&F12 -> 122259 - History - Mystery | J12: =D12*H12 -> 420.16 | K12: =IF(D12>0,1,0) -> 1
A13: =IFERROR(__xludf.DUMMYFUNCTION("""COMPUTED_VALUE"""),199526.0) -> 199526 | B13: =IFERROR(__xludf.DUMMYFUNCTION("""COMPUTED_VALUE"""),0.0) -> 0 | C13: =IFERROR(__xludf.DUMMYFUNCTION("""COMPUTED_VALUE"""),63.0) -> 63 | D13: =IFERROR(__xludf.DUMMYFUNCTION("""COMPUTED_VALUE"""),60.0) -> 60 | E13: {=_xlfn.XLOOKUP(A13,Product!A:A,Product!B:B,"Bulunamadı")} -> History | F13: {=_xlfn.XLOOKUP(A13,Product!A:A,Product!C:C,"Bulunamadı")} -> Mystery | G13: {=_xlfn.XLOOKUP(A14,Product!A:A,Product!D:D,"Bulunamadı")} -> Golden Quill Press | H13: {=_xlfn.XLOOKUP(A15,Product!A:A,Product!E:E,"Bulunamadı")} -> 1.5 | I13: =A13&" - "&E13&" - "&F13 -> 199526 - History - Mystery | J13: =D13*H13 -> 90 | K13: =IF(D13>0,1,0) -> 1
A14: =IFERROR(__xludf.DUMMYFUNCTION("""COMPUTED_VALUE"""),140581.0) -> 140581 | B14: =IFERROR(__xludf.DUMMYFUNCTION("""COMPUTED_VALUE"""),0.0) -> 0 | C14: =IFERROR(__xludf.DUMMYFUNCTION("""COMPUTED_VALUE"""),14.0) -> 14 | D14: =IFERROR(__xludf.DUMMYFUNCTION("""COMPUTED_VALUE"""),9.0) -> 9 | E14: {=_xlfn.XLOOKUP(A14,Product!A:A,Product!B:B,"Bulunamadı")} -> History | F14: {=_xlfn.XLOOKUP(A14,Product!A:A,Product!C:C,"Bulunamadı")} -> Mystery | G14: {=_xlfn.XLOOKUP(A15,Product!A:A,Product!D:D,"Bulunamadı")} -> Golden Quill Press | H14: {=_xlfn.XLOOKUP(A16,Product!A:A,Product!E:E,"Bulunamadı")} -> 2.65 | I14: =A14&" - "&E14&" - "&F14 -> 140581 - History - Mystery | J14: =D14*H14 -> 23.85 | K14: =IF(D14>0,1,0) -> 1
A15: =IFERROR(__xludf.DUMMYFUNCTION("""COMPUTED_VALUE"""),118383.0) -> 118383 | B15: =IFERROR(__xludf.DUMMYFUNCTION("""COMPUTED_VALUE"""),0.0) -> 0 | C15: =IFERROR(__xludf.DUMMYFUNCTION("""COMPUTED_VALUE"""),256.0) -> 256 | D15: =IFERROR(__xludf.DUMMYFUNCTION("""COMPUTED_VALUE"""),256.0) -> 256 | E15: {=_xlfn.XLOOKUP(A15,Product!A:A,Product!B:B,"Bulunamadı")} -> History | F15: {=_xlfn.XLOOKUP(A15,Product!A:A,Product!C:C,"Bulunamadı")} -> Mystery | G15: {=_xlfn.XLOOKUP(A16,Product!A:A,Product!D:D,"Bulunamadı")} -> Golden Quill Press | H15: {=_xlfn.XLOOKUP(A17,Product!A:A,Product!E:E,"Bulunamadı")} -> 2.04 | I15: =A15&" - "&E15&" - "&F15 -> 118383 - History - Mystery | J15: =D15*H15 -> 522.24 | K15: =IF(D15>0,1,0) -> 1
A16: =IFERROR(__xludf.DUMMYFUNCTION("""COMPUTED_VALUE"""),122262.0) -> 122262 | B16: =IFERROR(__xludf.DUMMYFUNCTION("""COMPUTED_VALUE"""),0.0) -> 0 | C16: =IFERROR(__xludf.DUMMYFUNCTION("""COMPUTED_VALUE"""),326.0) -> 326 | D16: =IFERROR(__xludf.DUMMYFUNCTION("""COMPUTED_VALUE"""),326.0) -> 326 | E16: {=_xlfn.XLOOKUP(A16,Product!A:A,Product!B:B,"Bulunamadı")} -> History | F16: {=_xlfn.XLOOKUP(A16,Product!A:A,Product!C:C,"Bulunamadı")} -> Mystery | G16: {=_xlfn.XLOOKUP(A17,Product!A:A,Product!D:D,"Bulunamadı")} -> Golden Quill Press | H16: {=_xlfn.XLOOKUP(A18,Product!A:A,Product!E:E,"Bulunamadı")} -> 2.88 | I16: =A16&" - "&E16&" - "&F16 -> 122262 - History - Mystery | J16: =D16*H16 -> 938.88 | K16: =IF(D16>0,1,0) -> 1
A17: =IFERROR(__xludf.DUMMYFUNCTION("""COMPUTED_VALUE"""),141879.0) -> 141879 | B17: =IFERROR(__xludf.DUMMYFUNCTION("""COMPUTED_VALUE"""),0.0) -> 0 | C17: =IFERROR(__xludf.DUMMYFUNCTION("""COMPUTED_VALUE"""),11.0) -> 11 | D17: =IFERROR(__xludf.DUMMYFUNCTION("""COMPUTED_VALUE"""),11.0) -> 11 | E17: {=_xlfn.XLOOKUP(A17,Product!A:A,Product!B:B,"Bulunamadı")} -> History | F17: {=_xlfn.XLOOKUP(A17,Product!A:A,Product!C:C,"Bulunamadı")} -> Mystery | G17: {=_xlfn.XLOOKUP(A18,Product!A:A,Product!D:D,"Bulunamadı")} -> Harbor Light Books | H17: {=_xlfn.XLOOKUP(A19,Product!A:A,Product!E:E,"Bulunamadı")} -> 3.23 | I17: =A17&" - "&E17&" - "&F17 -> 141879 - History - Mystery | J17: =D17*H17 -> 35.53 | K17: =IF(D17>0,1,0) -> 1
A18: =IFERROR(__xludf.DUMMYFUNCTION("""COMPUTED_VALUE"""),19826.0) -> 19826 | B18: =IFERROR(__xludf.DUMMYFUNCTION("""COMPUTED_VALUE"""),0.0) -> 0 | C18: =IFERROR(__xludf.DUMMYFUNCTION("""COMPUTED_VALUE"""),210.0) -> 210 | D18: =IFERROR(__xludf.DUMMYFUNCTION("""COMPUTED_VALUE"""),103.0) -> 103 | E18: {=_xlfn.XLOOKUP(A18,Product!A:A,Product!B:B,"Bulunamadı")} -> History | F18: {=_xlfn.XLOOKUP(A18,Product!A:A,Product!C:C,"Bulunamadı")} -> Thriller | G18: {=_xlfn.XLOOKUP(A19,Product!A:A,Product!D:D,"Bulunamadı")} -> Harbor Light Books | H18: {=_xlfn.XLOOKUP(A20,Product!A:A,Product!E:E,"Bulunamadı")} -> 4.72 | I18: =A18&" - "&E18&" - "&F18 -> 19826 - History - Thriller | J18: =D18*H18 -> 486.16 | K18: =IF(D18>0,1,0) -> 1
A19: =IFERROR(__xludf.DUMMYFUNCTION("""COMPUTED_VALUE"""),93039.0) -> 93039 | B19: =IFERROR(__xludf.DUMMYFUNCTION("""COMPUTED_VALUE"""),0.0) -> 0 | C19: =IFERROR(__xludf.DUMMYFUNCTION("""COMPUTED_VALUE"""),68.0) -> 68 | D19: =IFERROR(__xludf.DUMMYFUNCTION("""COMPUTED_VALUE"""),68.0) -> 68 | E19: {=_xlfn.XLOOKUP(A19,Product!A:A,Product!B:B,"Bulunamadı")} -> History | F19: {=_xlfn.XLOOKUP(A19,Product!A:A,Product!C:C,"Bulunamadı")} -> Thriller | G19: {=_xlfn.XLOOKUP(A20,Product!A:A,Product!D:D,"Bulunamadı")} -> Harbor Light Books | H19: {=_xlfn.XLOOKUP(A21,Product!A:A,Product!E:E,"Bulunamadı")} -> 6.05 | I19: =A19&" - "&E19&" - "&F19 -> 93039 - History - Thriller | J19: =D19*H19 -> 411.4 | K19: =IF(D19>0,1,0) -> 1
A20: =IFERROR(__xludf.DUMMYFUNCTION("""COMPUTED_VALUE"""),128213.0) -> 128213 | B20: =IFERROR(__xludf.DUMMYFUNCTION("""COMPUTED_VALUE"""),0.0) -> 0 | C20: =IFERROR(__xludf.DUMMYFUNCTION("""COMPUTED_VALUE"""),318.0) -> 318 | D20: =IFERROR(__xludf.DUMMYFUNCTION("""COMPUTED_VALUE"""),162.0) -> 162 | E20: {=_xlfn.XLOOKUP(A20,Product!A:A,Product!B:B,"Bulunamadı")} -> History | F20: {=_xlfn.XLOOKUP(A20,Product!A:A,Product!C:C,"Bulunamadı")} -> Thriller | G20: {=_xlfn.XLOOKUP(A21,Product!A:A,Product!D:D,"Bulunamadı")} -> Harbor Light Books | H20: {=_xlfn.XLOOKUP(A22,Product!A:A,Product!E:E,"Bulunamadı")} -> 3.86 | I20: =A20&" - "&E20&" - "&F20 -> 128213 - History - Thriller | J20: =D20*H20 -> 625.32 | K20: =IF(D20>0,1,0) -> 1
A21: =IFERROR(__xludf.DUMMYFUNCTION("""COMPUTED_VALUE"""),83797.0) -> 83797 | B21: =IFERROR(__xludf.DUMMYFUNCTION("""COMPUTED_VALUE"""),0.0) -> 0 | C21: =IFERROR(__xludf.DUMMYFUNCTION("""COMPUTED_VALUE"""),43.0) -> 43 | D21: =IFERROR(__xludf.DUMMYFUNCTION("""COMPUTED_VALUE"""),43.0) -> 43 | E21: {=_xlfn.XLOOKUP(A21,Product!A:A,Product!B:B,"Bulunamadı")} -> History | F21: {=_xlfn.XLOOKUP(A21,Product!A:A,Product!C:C,"Bulunamadı")} -> Thriller | G21: {=_xlfn.XLOOKUP(A22,Product!A:A,Product!D:D,"Bulunamadı")} -> Harbor Light Books | H21: {=_xlfn.XLOOKUP(A23,Product!A:A,Product!E:E,"Bulunamadı")} -> 2.31 | I21: =A21&" - "&E21&" - "&F21 -> 83797 - History - Thriller | J21: =D21*H21 -> 99.33 | K21: =IF(D21>0,1,0) -> 1
A22: =IFERROR(__xludf.DUMMYFUNCTION("""COMPUTED_VALUE"""),19831.0) -> 19831 | B22: =IFERROR(__xludf.DUMMYFUNCTION("""COMPUTED_VALUE"""),0.0) -> 0 | C22: =IFERROR(__xludf.DUMMYFUNCTION("""COMPUTED_VALUE"""),185.0) -> 185 | D22: =IFERROR(__xludf.DUMMYFUNCTION("""COMPUTED_VALUE"""),134.0) -> 134 | E22: {=_xlfn.XLOOKUP(A22,Product!A:A,Product!B:B,"Bulunamadı")} -> History | F22: {=_xlfn.XLOOKUP(A22,Product!A:A,Product!C:C,"Bulunamadı")} -> Thriller | G22: {=_xlfn.XLOOKUP(A23,Product!A:A,Product!D:D,"Bulunamadı")} -> Harbor Light Books | H22: {=_xlfn.XLOOKUP(A24,Product!A:A,Product!E:E,"Bulunamadı")} -> 7.35 | I22: =A22&" - "&E22&" - "&F22 -> 19831 - History - Thriller | J22: =D22*H22 -> 984.9 | K22: =IF(D22>0,1,0) -> 1
A23: =IFERROR(__xludf.DUMMYFUNCTION("""COMPUTED_VALUE"""),93025.0) -> 93025 | B23: =IFERROR(__xludf.DUMMYFUNCTION("""COMPUTED_VALUE"""),0.0) -> 0 | C23: =IFERROR(__xludf.DUMMYFUNCTION("""COMPUTED_VALUE"""),305.0) -> 305 | D23: =IFERROR(__xludf.DUMMYFUNCTION("""COMPUTED_VALUE"""),305.0) -> 305 | E23: {=_xlfn.XLOOKUP(A23,Product!A:A,Product!B:B,"Bulunamadı")} -> History | F23: {=_xlfn.XLOOKUP(A23,Product!A:A,Product!C:C,"Bulunamadı")} -> Thriller | G23: {=_xlfn.XLOOKUP(A24,Product!A:A,Product!D:D,"Bulunamadı")} -> Harbor Light Books | H23: {=_xlfn.XLOOKUP(A25,Product!A:A,Product!E:E,"Bulunamadı")} -> 7.02 | I23: =A23&" - "&E23&" - "&F23 -> 93025 - History - Thriller | J23: =D23*H23 -> 2141.1 | K23: =IF(D23>0,1,0) -> 1
A24: =IFERROR(__xludf.DUMMYFUNCTION("""COMPUTED_VALUE"""),81624.0) -> 81624 | B24: =IFERROR(__xludf.DUMMYFUNCTION("""COMPUTED_VALUE"""),1.0) -> 1 | C24: =IFERROR(__xludf.DUMMYFUNCTION("""COMPUTED_VALUE"""),84.0) -> 84 | D24: =IFERROR(__xludf.DUMMYFUNCTION("""COMPUTED_VALUE"""),84.0) -> 84 | E24: {=_xlfn.XLOOKUP(A24,Product!A:A,Product!B:B,"Bulunamadı")} -> History | F24: {=_xlfn.XLOOKUP(A24,Product!A:A,Product!C:C,"Bulunamadı")} -> Thriller | G24: {=_xlfn.XLOOKUP(A25,Product!A:A,Product!D:D,"Bulunamadı")} -> Harbor Light Books | H24: {=_xlfn.XLOOKUP(A26,Product!A:A,Product!E:E,"Bulunamadı")} -> 2.69 | I24: =A24&" - "&E24&" - "&F24 -> 81624 - History - Thriller | J24: =D24*H24 -> 225.96 | K24: =IF(D24>0,1,0) -> 1
A25: =IFERROR(__xludf.DUMMYFUNCTION("""COMPUTED_VALUE"""),92913.0) -> 92913 | B25: =IFERROR(__xludf.DUMMYFUNCTION("""COMPUTED_VALUE"""),0.0) -> 0 | C25: =IFERROR(__xludf.DUMMYFUNCTION("""COMPUTED_VALUE"""),96.0) -> 96 | D25: =IFERROR(__xludf.DUMMYFUNCTION("""COMPUTED_VALUE"""),96.0) -> 96 | E25: {=_xlfn.XLOOKUP(A25,Product!A:A,Product!B:B,"Bulunamadı")} -> History | F25: {=_xlfn.XLOOKUP(A25,Product!A:A,Product!C:C,"Bulunamadı")} -> Thriller | G25: {=_xlfn.XLOOKUP(A26,Product!A:A,Product!D:D,"Bulunamadı")} -> Harbor Light Books | H25: {=_xlfn.XLOOKUP(A27,Product!A:A,Product!E:E,"Bulunamadı")} -> 1.89 | I25: =A25&" - "&E25&" - "&F25 -> 92913 - History - Thriller | J25: =D25*H25 -> 181.44 | K25: =IF(D25>0,1,0) -> 1
A26: =IFERROR(__xludf.DUMMYFUNCTION("""COMPUTED_VALUE"""),126983.0) -> 126983 | B26: =IFERROR(__xludf.DUMMYFUNCTION("""COMPUTED_VALUE"""),0.0) -> 0 | C26: =IFERROR(__xludf.DUMMYFUNCTION("""COMPUTED_VALUE"""),176.0) -> 176 | D26: =IFERROR(__xludf.DUMMYFUNCTION("""COMPUTED_VALUE"""),71.0) -> 71 | E26: {=_xlfn.XLOOKUP(A26,Product!A:A,Product!B:B,"Bulunamadı")} -> History | F26: {=_xlfn.XLOOKUP(A26,Product!A:A,Product!C:C,"Bulunamadı")} -> Thriller | G26: {=_xlfn.XLOOKUP(A27,Product!A:A,Product!D:D,"Bulunamadı")} -> Harbor Light Books | H26: {=_xlfn.XLOOKUP(A28,Product!A:A,Product!E:E,"Bulunamadı")} -> 2.39 | I26: =A26&" - "&E26&" - "&F26 -> 126983 - History - Thriller | J26: =D26*H26 -> 169.69 | K26: =IF(D26>0,1,0) -> 1
